Workbook
Name Tb_lista_in_D: LISTA_IN!$A$2:$K$32
Name dato_colonna: GESTIONE!$N$1
Name dato_riga: GESTIONE!$J$13
Name LEGENDA: AGENDA!$B$2:$I$2
Name Impost_V_lista: V_LISTA!$D$1:$G$1
Name Check_V_lista: V_LISTA!$A$3:$C$50
Name Tb_MasterPlna_DB_D: #REF!
Name conversione_data_coordinata: GESTIONE!$M$48:$N$75
Name Tb_listone_D: #REF!

Sheet GESTIONE
H1: AGENDA | M1: GIORNI | N1: =TODAY()-M2 -> 4 | AS1: ultima riga | AT1: =COUNTIF(AT3:AT100,"<>")*1 -> 4 | AW1: CALENDARIO
I2: N° SETT OG | J2: =WEEKNUM(TODAY(),2)-1 -> 0 | M2: =J3+J2*7 -> 46020 | N2: =CHOOSE(WEEKDAY(M2, 2), "C", "D", "E", "F", "G", "H", "I") &let( parametro, VLOOKUP( M2 - WEEKDAY(M2, 2) + 1, $J$6:$K$9, 2, FALSE), calcolo, 3+12*(IF(parametro=0,4,parametro)-1), calcolo ) -> C3 | P2: A+++ | Q2: 1 | S2: =S3-7 -> 45992 | U2: =IFERROR(__xludf.DUMMYFUNCTION("IF(V_LISTA!$D$1= ""DATE in"", sort(UNIQUE( FILTER(Tb_lista_in[DATA_IN], Tb_lista_in[DATA_IN]<>0)) ), SORT(UNIQUE( FILTER(Tb_lista_in[DATA_SCAD], Tb_lista_in[DATA_SCAD]<>0)) ) )"),46019.0) -> 46019 | AP2: posiz. elementi | AW2: DATA IN | AX2: =Calendario!H1 -> 45872
I3: RIF data | J3: =DATE(YEAR(TODAY()),1,1) - WEEKDAY(DATE(YEAR(TODAY()),1,1),3) -> 46020 | M3: =M2+1 -> 46021 | N3: =CHOOSE(WEEKDAY(M3, 2), "C", "D", "E", "F", "G", "H", "I") &let( parametro, VLOOKUP( M3 - WEEKDAY(M3, 2) + 1, $J$6:$K$9, 2, FALSE), calcolo, 3+12*(IF(parametro=0,4,parametro)-1), calcolo ) -> D3 | P3: A | Q3: 2 | S3: =S4-7 -> 45999 | U3: =IFERROR(__xludf.DUMMYFUNCTION("""COMPUTED_VALUE"""),46021.0) -> 46021 | AO3: colonna AB | AP3: =COLUMN(AH2) -> 34 | AS3: COORDINATA | AT3: =5+ (IF(GESTIONE!J13-1=0, 4, GESTIONE!J13-1) -1)*12 -> 41 | AW3: DATA OUT | AX3: =Calendario!I1 -> 45879
M4: =M3+1 -> 46022 | N4: =CHOOSE(WEEKDAY(M4, 2), "C", "D", "E", "F", "G", "H", "I") &let( parametro, VLOOKUP( M4 - WEEKDAY(M4, 2) + 1, $J$6:$K$9, 2, FALSE), calcolo, 3+12*(IF(parametro=0,4,parametro)-1), calcolo ) -> E3 | P4: B | Q4: 3 | S4: =S5-7 -> 46006 | U4: =IFERROR(__xludf.DUMMYFUNCTION("""COMPUTED_VALUE"""),46022.0) -> 46022 | AS4: DA | AT4: {=INDEX(AGENDA!C:C,AT3-1)} -> 46041 | AW4: DATA RIF | AX4: =MIN(Calendario!C:C) -> 995
H5: calc. | I5: SETT. | J5: DAY | K5: n° | M5: =M4+1 -> 46023 | N5: =CHOOSE(WEEKDAY(M5, 2), "C", "D", "E", "F", "G", "H", "I") &let( parametro, VLOOKUP( M5 - WEEKDAY(M5, 2) + 1, $J$6:$K$9, 2, FALSE), calcolo, 3+12*(IF(parametro=0,4,parametro)-1), calcolo ) -> F3 | P5: C | Q5: 4 | S5: =S6-7 -> 46013 | U5: =IFERROR(__xludf.DUMMYFUNCTION("""COMPUTED_VALUE"""),46023.0) -> 46023 | AS5: A | AT5: {=INDEX(AGENDA!I:I,AT3-1)} -> 46047 | AW5: DATA XY | AX5: 3
H6: =IF( RIGHT($J$2/4,2)*1=25, $J$2, $J$2+K6-VLOOKUP(J2,H6:K9,4,FALSE)) -> 1 | I6: =IF(H6<=$J$2,H6+4,H6)-1 -> 0 | J6: =I6*7+$J$3 -> 46020 | K6: 1 | M6: =M5+1 -> 46024 | N6: =CHOOSE(WEEKDAY(M6, 2), "C", "D", "E", "F", "G", "H", "I") &let( parametro, VLOOKUP( M6 - WEEKDAY(M6, 2) + 1, $J$6:$K$9, 2, FALSE), calcolo, 3+12*(IF(parametro=0,4,parametro)-1), calcolo ) -> G3 | P6: C--- | Q6: 5 | S6: =TODAY() - WEEKDAY(TODAY(), 3) -> 46020 | U6: =IFERROR(__xludf.DUMMYFUNCTION("""COMPUTED_VALUE"""),46024.0) -> 46024 | AS6: N° ATTIVITA' | AT6: {=INDEX(AGENDA!J:J,AT3)} -> 0
H7: =IFERROR(IF( MID($J$2/4,FIND(",",$J$2/4)+1,1)*1=5, $J$2, $J$2+K7-VLOOKUP($J$2,H6:K9,4,FALSE) ),$J$2+K7-VLOOKUP($J$2,H6:K9,4,FALSE)) -> 2 | I7: =IF(H7<=$J$2,H7+4,H7)-1 -> 1 | J7: =I7*7+$J$3 -> 46027 | K7: 2 | M7: =M6+1 -> 46025 | N7: =CHOOSE(WEEKDAY(M7, 2), "C", "D", "E", "F", "G", "H", "I") &let( parametro, VLOOKUP( M7 - WEEKDAY(M7, 2) + 1, $J$6:$K$9, 2, FALSE), calcolo, 3+12*(IF(parametro=0,4,parametro)-1), calcolo ) -> H3 | S7: =S6+7 -> 46027 | U7: =IFERROR(__xludf.DUMMYFUNCTION("""COMPUTED_VALUE"""),46025.0) -> 46025 | AU7: test
H8: =IF( RIGHT($J$2/4,2)*1=75, $J$2, $J$2+K8-VLOOKUP($J$2,H6:K9,4,FALSE)) -> 3 | I8: =IF(H8<=$J$2,H8+4,H8)-1 -> 2 | J8: =I8*7+$J$3 -> 46034 | K8: 3 | M8: =M7+1 -> 46026 | N8: =CHOOSE(WEEKDAY(M8, 2), "C", "D", "E", "F", "G", "H", "I") &let( parametro, VLOOKUP( M8 - WEEKDAY(M8, 2) + 1, $J$6:$K$9, 2, FALSE), calcolo, 3+12*(IF(parametro=0,4,parametro)-1), calcolo ) -> I3 | S8: =S7+7 -> 46034 | U8: =IFERROR(__xludf.DUMMYFUNCTION("""COMPUTED_VALUE"""),46026.0) -> 46026
H9: =IF($J$2/4=int($J$2/4), $J$2, $J$2+4-VLOOKUP($J$2,H6:K9,4,FALSE)) -> 0 | I9: =IF(H9<=$J$2,H9+4,H9)-1 -> 3 | J9: =I9*7+$J$3 -> 46041 | K9: 0 | M9: =M8+1 -> 46027 | N9: =CHOOSE(WEEKDAY(M9, 2), "C", "D", "E", "F", "G", "H", "I") &let( parametro, VLOOKUP( M9 - WEEKDAY(M9, 2) + 1, $J$6:$K$9, 2, FALSE), calcolo, 3+12*(IF(parametro=0,4,parametro)-1), calcolo ) -> C15 | S9: =S8+7 -> 46041 | U9: =IFERROR(__xludf.DUMMYFUNCTION("""COMPUTED_VALUE"""),46027.0) -> 46027
M10: =M9+1 -> 46028 | N10: =CHOOSE(WEEKDAY(M10, 2), "C", "D", "E", "F", "G", "H", "I") &let( parametro, VLOOKUP( M10 - WEEKDAY(M10, 2) + 1, $J$6:$K$9, 2, FALSE), calcolo, 3+12*(IF(parametro=0,4,parametro)-1), calcolo ) -> D15 | S10: =S9+7 -> 46048 | U10: =IFERROR(__xludf.DUMMYFUNCTION("""COMPUTED_VALUE"""),46030.0) -> 46030
M11: =M10+1 -> 46029 | N11: =CHOOSE(WEEKDAY(M11, 2), "C", "D", "E", "F", "G", "H", "I") &let( parametro, VLOOKUP( M11 - WEEKDAY(M11, 2) + 1, $J$6:$K$9, 2, FALSE), calcolo, 3+12*(IF(parametro=0,4,parametro)-1), calcolo ) -> E15 | U11: =IFERROR(__xludf.DUMMYFUNCTION("""COMPUTED_VALUE"""),46032.0) -> 46032
M12: =M11+1 -> 46030 | N12: =CHOOSE(WEEKDAY(M12, 2), "C", "D", "E", "F", "G", "H", "I") &let( parametro, VLOOKUP( M12 - WEEKDAY(M12, 2) + 1, $J$6:$K$9, 2, FALSE), calcolo, 3+12*(IF(parametro=0,4,parametro)-1), calcolo ) -> F15 | U12: =IFERROR(__xludf.DUMMYFUNCTION("""COMPUTED_VALUE"""),46033.0) -> 46033
I13: Coordinata | J13: =IF( VLOOKUP(J2,I6:K9,3,FALSE)=0, 4, VLOOKUP(J2,I6:K9,3,FALSE) ) -> 1 | M13: =M12+1 -> 46031 | N13: =CHOOSE(WEEKDAY(M13, 2), "C", "D", "E", "F", "G", "H", "I") &let( parametro, VLOOKUP( M13 - WEEKDAY(M13, 2) + 1, $J$6:$K$9, 2, FALSE), calcolo, 3+12*(IF(parametro=0,4,parametro)-1), calcolo ) -> G15 | U13: =IFERROR(__xludf.DUMMYFUNCTION("""COMPUTED_VALUE"""),46054.0) -> 46054
M14: =M13+1 -> 46032 | N14: =CHOOSE(WEEKDAY(M14, 2), "C", "D", "E", "F", "G", "H", "I") &let( parametro, VLOOKUP( M14 - WEEKDAY(M14, 2) + 1, $J$6:$K$9, 2, FALSE), calcolo, 3+12*(IF(parametro=0,4,parametro)-1), calcolo ) -> H15
M15: =M14+1 -> 46033 | N15: =CHOOSE(WEEKDAY(M15, 2), "C", "D", "E", "F", "G", "H", "I") &let( parametro, VLOOKUP( M15 - WEEKDAY(M15, 2) + 1, $J$6:$K$9, 2, FALSE), calcolo, 3+12*(IF(parametro=0,4,parametro)-1), calcolo ) -> I15
M16: =M15+1 -> 46034 | N16: =CHOOSE(WEEKDAY(M16, 2), "C", "D", "E", "F", "G", "H", "I") &let( parametro, VLOOKUP( M16 - WEEKDAY(M16, 2) + 1, $J$6:$K$9, 2, FALSE), calcolo, 3+12*(IF(parametro=0,4,parametro)-1), calcolo ) -> C27
M17: =M16+1 -> 46035 | N17: =CHOOSE(WEEKDAY(M17, 2), "C", "D", "E", "F", "G", "H", "I") &let( parametro, VLOOKUP( M17 - WEEKDAY(M17, 2) + 1, $J$6:$K$9, 2, FALSE), calcolo, 3+12*(IF(parametro=0,4,parametro)-1), calcolo ) -> D27
M18: =M17+1 -> 46036 | N18: =CHOOSE(WEEKDAY(M18, 2), "C", "D", "E", "F", "G", "H", "I") &let( parametro, VLOOKUP( M18 - WEEKDAY(M18, 2) + 1, $J$6:$K$9, 2, FALSE), calcolo, 3+12*(IF(parametro=0,4,parametro)-1), calcolo ) -> E27
M19: =M18+1 -> 46037 | N19: =CHOOSE(WEEKDAY(M19, 2), "C", "D", "E", "F", "G", "H", "I") &let( parametro, VLOOKUP( M19 - WEEKDAY(M19, 2) + 1, $J$6:$K$9, 2, FALSE), calcolo, 3+12*(IF(parametro=0,4,parametro)-1), calcolo ) -> F27
M20: =M19+1 -> 46038 | N20: =CHOOSE(WEEKDAY(M20, 2), "C", "D", "E", "F", "G", "H", "I") &let( parametro, VLOOKUP( M20 - WEEKDAY(M20, 2) + 1, $J$6:$K$9, 2, FALSE), calcolo, 3+12*(IF(parametro=0,4,parametro)-1), calcolo ) -> G27
M21: =M20+1 -> 46039 | N21: =CHOOSE(WEEKDAY(M21, 2), "C", "D", "E", "F", "G", "H", "I") &let( parametro, VLOOKUP( M21 - WEEKDAY(M21, 2) + 1, $J$6:$K$9, 2, FALSE), calcolo, 3+12*(IF(parametro=0,4,parametro)-1), calcolo ) -> H27
M22: =M21+1 -> 46040 | N22: =CHOOSE(WEEKDAY(M22, 2), "C", "D", "E", "F", "G", "H", "I") &let( parametro, VLOOKUP( M22 - WEEKDAY(M22, 2) + 1, $J$6:$K$9, 2, FALSE), calcolo, 3+12*(IF(parametro=0,4,parametro)-1), calcolo ) -> I27
M23: =M22+1 -> 46041 | N23: =CHOOSE(WEEKDAY(M23, 2), "C", "D", "E", "F", "G", "H", "I") &let( parametro, VLOOKUP( M23 - WEEKDAY(M23, 2) + 1, $J$6:$K$9, 2, FALSE), calcolo, 3+12*(IF(parametro=0,4,parametro)-1), calcolo ) -> C39
M24: =M23+1 -> 46042 | N24: =CHOOSE(WEEKDAY(M24, 2), "C", "D", "E", "F", "G", "H", "I") &let( parametro, VLOOKUP( M24 - WEEKDAY(M24, 2) + 1, $J$6:$K$9, 2, FALSE), calcolo, 3+12*(IF(parametro=0,4,parametro)-1), calcolo ) -> D39
M25: =M24+1 -> 46043 | N25: =CHOOSE(WEEKDAY(M25, 2), "C", "D", "E", "F", "G", "H", "I") &let( parametro, VLOOKUP( M25 - WEEKDAY(M25, 2) + 1, $J$6:$K$9, 2, FALSE), calcolo, 3+12*(IF(parametro=0,4,parametro)-1), calcolo ) -> E39
... M29: =M28+1 -> 46047 | N29: =CHOOSE(WEEKDAY(M29, 2), "C", "D", "E", "F", "G", "H", "I") &let( parametro, VLOOKUP( M29 - WEEKDAY(M29, 2) + 1, $J$6:$K$9, 2, FALSE), calcolo, 3+12*(IF(parametro=0,4,parametro)-1), calcolo ) -> I39
M47: INTERVALLO DENOMINATO
M48: =TEXT(M2, "ddd dd/mm") -> lun 29/12 | N48: =N2 -> C3
M49: =TEXT(M3, "ddd dd/mm") -> mar 30/12 | N49: =N3 -> D3
M50: =TEXT(M4, "ddd dd/mm") -> mer 31/12 | N50: =N4 -> E3
M51: =TEXT(M5, "ddd dd/mm") -> gio 01/01 | N51: =N5 -> F3
M52: =TEXT(M6, "ddd dd/mm") -> ven 02/01 | N52: =N6 -> G3
M53: =TEXT(M7, "ddd dd/mm") -> sab 03/01 | N53: =N7 -> H3
M54: =TEXT(M8, "ddd dd/mm") -> dom 04/01 | N54: =N8 -> I3
M55: =TEXT(M9, "ddd dd/mm") -> lun 05/01 | N55: =N9 -> C15
M56: =TEXT(M10, "ddd dd/mm") -> mar 06/01 | N56: =N10 -> D15
M57: =TEXT(M11, "ddd dd/mm") -> mer 07/01 | N57: =N11 -> E15
M58: =TEXT(M12, "ddd dd/mm") -> gio 08/01 | N58: =N12 -> F15
M59: =TEXT(M13, "ddd dd/mm") -> ven 09/01 | N59: =N13 -> G15
... M75: =TEXT(M29, "ddd dd/mm") -> dom 25/01 | N75: =N29 -> I39

Sheet AGENDA
C1: FESTIVITÀ | D1: BECK UP; gg 1
A2: # * s | C2: \ Lavoro: eventi | D2: | lavoro: "norma" | E2: ! laovri di gruppo | F2: " HOBBY | G2: £ altre mie attività | H2: ç family | I2: ^ RIPOSO | J2: CALENDER | K2: =IF( SUM(J5,J17,J29,J41)=SUM(K5,K17,K29,K41), "tutto ok", "da vedere!") -> da vedere! | N2: VISUALLIZA | O2: 1- PC
N3: =IFERROR(__xludf.DUMMYFUNCTION("IF(O2=""1- PC"", """", FILTER(GESTIONE!AS:AT,GESTIONE!AS:AS<>0) )"),"")
A4: =GESTIONE!J6 -> 46020 | C4: =A4 -> 46020 | D4: =C4+1 -> 46021 | E4: =D4+1 -> 46022 | F4: =E4+1 -> 46023 | G4: =F4+1 -> 46024 | H4: =G4+1 -> 46025 | I4: =H4+1 -> 46026 | J4: CALENDER | K4: VER
C5: #£ Organizzare attività + sveglie | F5: #£ verifica agg calendario + beck up | J5: =SUMIFS( Calendario!A:A, Calendario!C:C,">="&A4, Calendario!C:C,"<="&I4) -> 0 | K5: 4
A6: M. | B6: 8-10 | K6: =IF( J5=K5, "tutto ok", "da vedere!") -> da vedere!
B7: 10-12 | C7: £ Es di inglese | E7: £ Es di inglese | G7: £ Es di inglese | I7: £ Es di inglese
A8: P. | B8: 12-14
B9: 14-16
B10: 16-18 | C10: ^PALESTRA | G10: ^ PALESTRA: gambe
B11: 18-20 | E11: ^PALESTRA: petto | I11: ^ palestra: 18.00
A12: S. | B12: 20-22 | C12: *" GIOCHI in scatola | D12: * | E12: *" cena con amici | F12: * | G12: *" Giochi in scatola | H12: * | I12: *
B13: 22-24
A16: =GESTIONE!J7 -> 46027 | C16: =A16 -> 46027 | D16: =C16+1 -> 46028 | E16: =D16+1 -> 46029 | F16: =E16+1 -> 46030 | G16: =F16+1 -> 46031 | H16: =G16+1 -> 46032 | I16: =H16+1 -> 46033 | J16: CALENDER | K16: VER
C17: #£ Organizzare attività + sveglie | D17: #£ Monopattino | E17: #\ lavoro - esame xxx | H17: #£ abbonamento treno + sveglie | J17: =SUMIFS( Calendario!A:A, Calendario!C:C,">="&A16, Calendario!C:C,"<="&I16) -> 0 | K17: 1
A18: M. | B18: 8-10 | E18: | Lavoro / studio 9.00 - 18.00 | G18: | Lavoro / studio 9.00 - 18.00 | I18: ^ trekking | K18: =IF( J17=K17, "tutto ok", "da vedere!") -> da vedere!
B19: 10-12 | F19: £ Es di inglese | H19: £ Es di inglese
A20: P. | B20: 12-14
B21: 14-16
B22: 16-18
B23: 18-20 | D23: ^PALESTRA: petto | F23: ^ padel 18.30-20.00
A24: S. | B24: 20-22 | C24: *" GIOCHI in scatola | D24: * | E24: * | G24: *" Giochi Vigevao 21.00 | H24: * | I24: *
B25: 22-24
A28: =GESTIONE!J8 -> 46034 | C28: =A28 -> 46034 | D28: =C28+1 -> 46035 | E28: =D28+1 -> 46036 | F28: =E28+1 -> 46037 | G28: =F28+1 -> 46038 | H28: =G28+1 -> 46039 | I28: =H28+1 -> 46040 | J28: CALENDER | K28: VER
C29: #£ Organizzare attività + sveglie | J29: =SUMIFS( Calendario!A:A, Calendario!C:C,">="&A28, Calendario!C:C,"<="&I28) -> 0 | K29: 0
A30: M. | B30: 8-10 | E30: | Lavoro / studio 9.00 - 18.00 | F30: | Lavoro / studio 9.00 - 18.00 | G30: | Lavoro / studio 9.00 - 18.00 | K30: =IF( J29=K29, "tutto ok", "da vedere!") -> tutto ok
B31: 10-12 | C31: £ Es di inglese | D31: £ Es di inglese | H31: £ Es di inglese | I31: £ Es di inglese
A32: P. | B32: 12-14
B33: 14-16 | C33: | Lavoro/studio 14.00 - 18.00
B34: 16-18
B35: 18-20 | D35: ^PALESTRA: petto | F35: ^ PALESTRA: gambe | I35: ^ palestra: 18.00
A36: S. | B36: 20-22 | C36: *" GIOCHI in scatola | D36: * | E36: * | G36: *" Giochi Vigevao 21.00 | H36: * | I36: *
B37: 22-24
A40: =GESTIONE!J9 -> 46041 | C40: =A40 -> 46041 | D40: =C40+1 -> 46042 | E40: =D40+1 -> 46043 | F40: =E40+1 -> 46044 | G40: =F40+1 -> 46045 | H40: =G40+1 -> 46046 | I40: =H40+1 -> 46047 | J40: CALENDER | K40: VER
C41: #£ Organizzare attività + sveglie | D41: \ Lavoro: visita di xxx | J41: =SUMIFS( Calendario!A:A, Calendario!C:C,">="&A40, Calendario!C:C,"<="&I40) -> 0 | K41: 1
A42: M. | B42: 8-10 | D42: | Lavoro/sudio 9.00 - 13.00 | E42: | Lavoro / studio 9.00 - 18.00 | F42: | Lavoro/sudio 9.00 - 13.00 | G42: | Lavoro / studio 9.00 - 18.00 | K42: =IF( J41=K41, "tutto ok", "da vedere!") -> da vedere!
B43: 10-12 | C43: £ Es di inglese | H43: £ Es di inglese | I43: £ Es di inglese
A44: P. | B44: 12-14
B45: 14-16 | C45: | Lavoro/studio 14.00 - 18.00
B46: 16-18
...

Sheet Calendario
C1: 995 | E1: AGG. GESTIONALE | G1: IN DATE | H1: 45872 | I1: =H1+7 -> 45879 | J1: SALVARE
A2: SP Q. | B2: SP T. | C2: GIORNO | D2: Gen 1 | E2: Gen 2 | F2: 8.00 - 10.00 | G2: 10.00 - 12.00 | H2: 12.00 - 13.00 | I2: 13.00 - 15.00 | J2: 15.00 - 17.00 | K2: 17.00 - 19.00 | L2: 19.00 - 20.00 | M2: 20.00 - 22.00 | N2: 22.00 - 24.00
A3: =COUNTIF(D3:N3,"<>0")-COUNTIF(D3:N3,">0") -> 0 | B3: =IFERROR(__xludf.DUMMYFUNCTION("IFERROR( TEXTJOIN("" \ "",TRUE,FILTER(D3:N3,ISNUMBER(D3:N3)=FALSE)) ,"""")"),"") | C3: 45536
A4: =COUNTIF(D4:N4,"<>0")-COUNTIF(D4:N4,">0") -> 0 | B4: =IFERROR(__xludf.DUMMYFUNCTION("IFERROR( TEXTJOIN("" \ "",TRUE,FILTER(D4:N4,ISNUMBER(D4:N4)=FALSE)) ,"""")"),"") | C4: 45537
A5: =COUNTIF(D5:N5,"<>0")-COUNTIF(D5:N5,">0") -> 0 | B5: =IFERROR(__xludf.DUMMYFUNCTION("IFERROR( TEXTJOIN("" \ "",TRUE,FILTER(D5:N5,ISNUMBER(D5:N5)=FALSE)) ,"""")"),"") | C5: 45538
A6: =COUNTIF(D6:N6,"<>0")-COUNTIF(D6:N6,">0") -> 0 | B6: =IFERROR(__xludf.DUMMYFUNCTION("IFERROR( TEXTJOIN("" \ "",TRUE,FILTER(D6:N6,ISNUMBER(D6:N6)=FALSE)) ,"""")"),"") | C6: 45539
A7: =COUNTIF(D7:N7,"<>0")-COUNTIF(D7:N7,">0") -> 0 | B7: =IFERROR(__xludf.DUMMYFUNCTION("IFERROR( TEXTJOIN("" \ "",TRUE,FILTER(D7:N7,ISNUMBER(D7:N7)=FALSE)) ,"""")"),"") | C7: 45540
A8: =COUNTIF(D8:N8,"<>0")-COUNTIF(D8:N8,">0") -> 0 | B8: =IFERROR(__xludf.DUMMYFUNCTION("IFERROR( TEXTJOIN("" \ "",TRUE,FILTER(D8:N8,ISNUMBER(D8:N8)=FALSE)) ,"""")"),"") | C8: 45541
A9: =COUNTIF(D9:N9,"<>0")-COUNTIF(D9:N9,">0") -> 0 | B9: =IFERROR(__xludf.DUMMYFUNCTION("IFERROR( TEXTJOIN("" \ "",TRUE,FILTER(D9:N9,ISNUMBER(D9:N9)=FALSE)) ,"""")"),"") | C9: 45542
A10: =COUNTIF(D10:N10,"<>0")-COUNTIF(D10:N10,">0") -> 0 | B10: =IFERROR(__xludf.DUMMYFUNCTION("IFERROR( TEXTJOIN("" \ "",TRUE,FILTER(D10:N10,ISNUMBER(D10:N10)=FALSE)) ,"""")"),"") | C10: 45543
A11: =COUNTIF(D11:N11,"<>0")-COUNTIF(D11:N11,">0") -> 0 | B11: =IFERROR(__xludf.DUMMYFUNCTION("IFERROR( TEXTJOIN("" \ "",TRUE,FILTER(D11:N11,ISNUMBER(D11:N11)=FALSE)) ,"""")"),"") | C11: 45544
A12: =COUNTIF(D12:N12,"<>0")-COUNTIF(D12:N12,">0") -> 0 | B12: =IFERROR(__xludf.DUMMYFUNCTION("IFERROR( TEXTJOIN("" \ "",TRUE,FILTER(D12:N12,ISNUMBER(D12:N12)=FALSE)) ,"""")"),"") | C12: 45545
A13: =COUNTIF(D13:N13,"<>0")-COUNTIF(D13:N13,">0") -> 0 | B13: =IFERROR(__xludf.DUMMYFUNCTION("IFERROR( TEXTJOIN("" \ "",TRUE,FILTER(D13:N13,ISNUMBER(D13:N13)=FALSE)) ,"""")"),"") | C13: 45546
A14: =COUNTIF(D14:N14,"<>0")-COUNTIF(D14:N14,">0") -> 0 | B14: =IFERROR(__xludf.DUMMYFUNCTION("IFERROR( TEXTJOIN("" \ "",TRUE,FILTER(D14:N14,ISNUMBER(D14:N14)=FALSE)) ,"""")"),"") | C14: 45547
A15: =COUNTIF(D15:N15,"<>0")-COUNTIF(D15:N15,">0") -> 0 | B15: =IFERROR(__xludf.DUMMYFUNCTION("IFERROR( TEXTJOIN("" \ "",TRUE,FILTER(D15:N15,ISNUMBER(D15:N15)=FALSE)) ,"""")"),"") | C15: 45548
A16: =COUNTIF(D16:N16,"<>0")-COUNTIF(D16:N16,">0") -> 0 | B16: =IFERROR(__xludf.DUMMYFUNCTION("IFERROR( TEXTJOIN("" \ "",TRUE,FILTER(D16:N16,ISNUMBER(D16:N16)=FALSE)) ,"""")"),"") | C16: 45549
A17: =COUNTIF(D17:N17,"<>0")-COUNTIF(D17:N17,">0") -> 0 | B17: =IFERROR(__xludf.DUMMYFUNCTION("IFERROR( TEXTJOIN("" \ "",TRUE,FILTER(D17:N17,ISNUMBER(D17:N17)=FALSE)) ,"""")"),"") | C17: 45550
A18: =COUNTIF(D18:N18,"<>0")-COUNTIF(D18:N18,">0") -> 0 | B18: =IFERROR(__xludf.DUMMYFUNCTION("IFERROR( TEXTJOIN("" \ "",TRUE,FILTER(D18:N18,ISNUMBER(D18:N18)=FALSE)) ,"""")"),"") | C18: 45551
A19: =COUNTIF(D19:N19,"<>0")-COUNTIF(D19:N19,">0") -> 0 | B19: =IFERROR(__xludf.DUMMYFUNCTION("IFERROR( TEXTJOIN("" \ "",TRUE,FILTER(D19:N19,ISNUMBER(D19:N19)=FALSE)) ,"""")"),"") | C19: 45552
A20: =COUNTIF(D20:N20,"<>0")-COUNTIF(D20:N20,">0") -> 0 | B20: =IFERROR(__xludf.DUMMYFUNCTION("IFERROR( TEXTJOIN("" \ "",TRUE,FILTER(D20:N20,ISNUMBER(D20:N20)=FALSE)) ,"""")"),"") | C20: 45553
A21: =COUNTIF(D21:N21,"<>0")-COUNTIF(D21:N21,">0") -> 0 | B21: =IFERROR(__xludf.DUMMYFUNCTION("IFERROR( TEXTJOIN("" \ "",TRUE,FILTER(D21:N21,ISNUMBER(D21:N21)=FALSE)) ,"""")"),"") | C21: 45554
A22: =COUNTIF(D22:N22,"<>0")-COUNTIF(D22:N22,">0") -> 0 | B22: =IFERROR(__xludf.DUMMYFUNCTION("IFERROR( TEXTJOIN("" \ "",TRUE,FILTER(D22:N22,ISNUMBER(D22:N22)=FALSE)) ,"""")"),"") | C22: 45555
A23: =COUNTIF(D23:N23,"<>0")-COUNTIF(D23:N23,">0") -> 0 | B23: =IFERROR(__xludf.DUMMYFUNCTION("IFERROR( TEXTJOIN("" \ "",TRUE,FILTER(D23:N23,ISNUMBER(D23:N23)=FALSE)) ,"""")"),"") | C23: 45556
A24: =COUNTIF(D24:N24,"<>0")-COUNTIF(D24:N24,">0") -> 0 | B24: =IFERROR(__xludf.DUMMYFUNCTION("IFERROR( TEXTJOIN("" \ "",TRUE,FILTER(D24:N24,ISNUMBER(D24:N24)=FALSE)) ,"""")"),"") | C24: 45557
A25: =COUNTIF(D25:N25,"<>0")-COUNTIF(D25:N25,">0") -> 0 | B25: =IFERROR(__xludf.DUMMYFUNCTION("IFERROR( TEXTJOIN("" \ "",TRUE,FILTER(D25:N25,ISNUMBER(D25:N25)=FALSE)) ,"""")"),"") | C25: 45558
A26: =COUNTIF(D26:N26,"<>0")-COUNTIF(D26:N26,">0") -> 0 | B26: =IFERROR(__xludf.DUMMYFUNCTION("IFERROR( TEXTJOIN("" \ "",TRUE,FILTER(D26:N26,ISNUMBER(D26:N26)=FALSE)) ,"""")"),"") | C26: 45559
A27: =COUNTIF(D27:N27,"<>0")-COUNTIF(D27:N27,">0") -> 0 | B27: =IFERROR(__xludf.DUMMYFUNCTION("IFERROR( TEXTJOIN("" \ "",TRUE,FILTER(D27:N27,ISNUMBER(D27:N27)=FALSE)) ,"""")"),"") | C27: 45560
A28: =COUNTIF(D28:N28,"<>0")-COUNTIF(D28:N28,">0") -> 0 | B28: =IFERROR(__xludf.DUMMYFUNCTION("IFERROR( TEXTJOIN("" \ "",TRUE,FILTER(D28:N28,ISNUMBER(D28:N28)=FALSE)) ,"""")"),"") | C28: 45561
A29: =COUNTIF(D29:N29,"<>0")-COUNTIF(D29:N29,">0") -> 0 | B29: =IFERROR(__xludf.DUMMYFUNCTION("IFERROR( TEXTJOIN("" \ "",TRUE,FILTER(D29:N29,ISNUMBER(D29:N29)=FALSE)) ,"""")"),"") | C29: 45562
A30: =COUNTIF(D30:N30,"<>0")-COUNTIF(D30:N30,">0") -> 0 | B30: =IFERROR(__xludf.DUMMYFUNCTION("IFERROR( TEXTJOIN("" \ "",TRUE,FILTER(D30:N30,ISNUMBER(D30:N30)=FALSE)) ,"""")"),"") | C30: 45563
A31: =COUNTIF(D31:N31,"<>0")-COUNTIF(D31:N31,">0") -> 0 | B31: =IFERROR(__xludf.DUMMYFUNCTION("IFERROR( TEXTJOIN("" \ "",TRUE,FILTER(D31:N31,ISNUMBER(D31:N31)=FALSE)) ,"""")"),"") | C31: 45564
A32: =COUNTIF(D32:N32,"<>0")-COUNTIF(D32:N32,">0") -> 0 | B32: =IFERROR(__xludf.DUMMYFUNCTION("IFERROR( TEXTJOIN("" \ "",TRUE,FILTER(D32:N32,ISNUMBER(D32:N32)=FALSE)) ,"""")"),"") | C32: 45565
A33: =COUNTIF(D33:N33,"<>0")-COUNTIF(D33:N33,">0") -> 0 | B33: =IFERROR(__xludf.DUMMYFUNCTION("IFERROR( TEXTJOIN("" \ "",TRUE,FILTER(D33:N33,ISNUMBER(D33:N33)=FALSE)) ,"""")"),"") | C33: 45566
A34: =COUNTIF(D34:N34,"<>0")-COUNTIF(D34:N34,">0") -> 0 | B34: =IFERROR(__xludf.DUMMYFUNCTION("IFERROR( TEXTJOIN("" \ "",TRUE,FILTER(D34:N34,ISNUMBER(D34:N34)=FALSE)) ,"""")"),"") | C34: 45567
A35: =COUNTIF(D35:N35,"<>0")-COUNTIF(D35:N35,">0") -> 0 | B35: =IFERROR(__xludf.DUMMYFUNCTION("IFERROR( TEXTJOIN("" \ "",TRUE,FILTER(D35:N35,ISNUMBER(D35:N35)=FALSE)) ,"""")"),"") | C35: 45568
A36: =COUNTIF(D36:N36,"<>0")-COUNTIF(D36:N36,">0") -> 0 | B36: =IFERROR(__xludf.DUMMYFUNCTION("IFERROR( TEXTJOIN("" \ "",TRUE,FILTER(D36:N36,ISNUMBER(D36:N36)=FALSE)) ,"""")"),"") | C36: 45569
A37: =COUNTIF(D37:N37,"<>0")-COUNTIF(D37:N37,">0") -> 0 | B37: =IFERROR(__xludf.DUMMYFUNCTION("IFERROR( TEXTJOIN("" \ "",TRUE,FILTER(D37:N37,ISNUMBER(D37:N37)=FALSE)) ,"""")"),"") | C37: 45570
A38: =COUNTIF(D38:N38,"<>0")-COUNTIF(D38:N38,">0") -> 0 | B38: =IFERROR(__xludf.DUMMYFUNCTION("IFERROR( TEXTJOIN("" \ "",TRUE,FILTER(D38:N38,ISNUMBER(D38:N38)=FALSE)) ,"""")"),"") | C38: 45571
A39: =COUNTIF(D39:N39,"<>0")-COUNTIF(D39:N39,">0") -> 0 | B39: =IFERROR(__xludf.DUMMYFUNCTION("IFERROR( TEXTJOIN("" \ "",TRUE,FILTER(D39:N39,ISNUMBER(D39:N39)=FALSE)) ,"""")"),"") | C39: 45572
A40: =COUNTIF(D40:N40,"<>0")-COUNTIF(D40:N40,">0") -> 0 | B40: =IFERROR(__xludf.DUMMYFUNCTION("IFERROR( TEXTJOIN("" \ "",TRUE,FILTER(D40:N40,ISNUMBER(D40:N40)=FALSE)) ,"""")"),"") | C40: 45573
...

Sheet Ore lavoro
F1: =F3/2000 -> 0.056 | G1: =G3/400 -> 0.00075
A2: SETT | B2: S/A | C2: ORE | D2: ASS | E2: USC A. | F2: ORE TOT | G2: TOT ASS | H2: ORE EXTRA | I2: MOTIVAZIONE
C3: =LET( intervallo, C4:C66, ore_totali_reali, SUMPRODUCT( INT(intervallo) + (intervallo - INT(intervallo)) * 100 / 60 ), risultato_ore_intere, INT(ore_totali_reali), risultato_minuti_fittizi, (ore_totali_reali - risultato_ore_intere) * 60 / 100, risultato_ore_intere + risultato_minuti_fittizi ) -> 111.3 | D3: =LET( intervallo, D4:D66, ore_totali_reali, SUMPRODUCT( INT(intervallo) + (intervallo - INT(intervallo)) * 100 / 60 ), risultato_ore_intere, INT(ore_totali_reali), risultato_minuti_fittizi, (ore_totali_reali - risultato_ore_intere) * 60 / 100, risultato_ore_intere + risultato_minuti_fittizi ) -> 0.25 | E3: =LET( intervallo, E4:E66, ore_totali_reali, SUMPRODUCT( INT(intervallo) + (intervallo - INT(intervallo)) * 100 / 60 ), risultato_ore_intere, INT(ore_totali_reali), risultato_minuti_fittizi, (ore_totali_reali - risultato_ore_intere) * 60 / 100, risultato_ore_intere + risultato_minuti_fittizi ) -> 0.05 | F3: =LET( intervallo, F4:F66, ore_totali_reali, SUMPRODUCT( INT(intervallo) + (intervallo - INT(intervallo)) * 100 / 60 ), risultato_ore_intere, INT(ore_totali_reali), risultato_minuti_fittizi, (ore_totali_reali - risultato_ore_intere) * 60 / 100, risultato_ore_intere + risultato_minuti_fittizi ) -> 112 | G3: =LET( intervallo, G4:G66, ore_totali_reali, SUMPRODUCT( INT(intervallo) + (intervallo - INT(intervallo)) * 100 / 60 ), risultato_ore_intere, INT(ore_totali_reali), risultato_minuti_fittizi, (ore_totali_reali - risultato_ore_intere) * 60 / 100, risultato_ore_intere + risultato_minuti_fittizi ) -> 0.3 | H3: =LET( intervallo, H4:H66, ore_totali_reali, SUMPRODUCT( INT(intervallo) + (intervallo - INT(intervallo)) * 100 / 60 ), risultato_ore_intere, INT(ore_totali_reali), risultato_minuti_fittizi, (ore_totali_reali - risultato_ore_intere) * 60 / 100, risultato_ore_intere + risultato_minuti_fittizi ) -> 1
A4: 45 | B4: =A4&"/25" -> 45/25 | C4: 16.35 | D4: 0.25 | F4: =LET( intervallo, C4:E4, ore_totali_reali, SUMPRODUCT( INT(intervallo) + (intervallo - INT(intervallo)) * 100 / 60 ), risultato_ore_intere, INT(ore_totali_reali), risultato_minuti_fittizi, (ore_totali_reali - risultato_ore_intere) * 60 / 100, risultato_ore_intere + risultato_minuti_fittizi ) -> 17 | G4: =LET( intervallo, D4:E4, ore_totali_reali, SUMPRODUCT( INT(intervallo) + (intervallo - INT(intervallo)) * 100 / 60 ), risultato_ore_intere, INT(ore_totali_reali), risultato_minuti_fittizi, (ore_totali_reali - risultato_ore_intere) * 60 / 100, risultato_ore_intere + risultato_minuti_fittizi ) -> 0.25
A5: 46 | B5: =A5&"/25" -> 46/25 | C5: 15 | F5: =LET( intervallo, C5:E5, ore_totali_reali, SUMPRODUCT( INT(intervallo) + (intervallo - INT(intervallo)) * 100 / 60 ), risultato_ore_intere, INT(ore_totali_reali), risultato_minuti_fittizi, (ore_totali_reali - risultato_ore_intere) * 60 / 100, risultato_ore_intere + risultato_minuti_fittizi ) -> 15 | G5: =LET( intervallo, D5:E5, ore_totali_reali, SUMPRODUCT( INT(intervallo) + (intervallo - INT(intervallo)) * 100 / 60 ), risultato_ore_intere, INT(ore_totali_reali), risultato_minuti_fittizi, (ore_totali_reali - risultato_ore_intere) * 60 / 100, risultato_ore_intere + risultato_minuti_fittizi ) -> 0 | H5: 1 | I5: "per ore della prof"
A6: 47 | B6: =A6&"/25" -> 47/25 | C6: =3.55+4+8 -> 15.55 | E6: 0.05 | F6: =LET( intervallo, C6:E6, ore_totali_reali, SUMPRODUCT( INT(intervallo) + (intervallo - INT(intervallo)) * 100 / 60 ), risultato_ore_intere, INT(ore_totali_reali), risultato_minuti_fittizi, (ore_totali_reali - risultato_ore_intere) * 60 / 100, risultato_ore_intere + risultato_minuti_fittizi ) -> 16 | G6: =LET( intervallo, D6:E6, ore_totali_reali, SUMPRODUCT( INT(intervallo) + (intervallo - INT(intervallo)) * 100 / 60 ), risultato_ore_intere, INT(ore_totali_reali), risultato_minuti_fittizi, (ore_totali_reali - risultato_ore_intere) * 60 / 100, risultato_ore_intere + risultato_minuti_fittizi ) -> 0.05
A7: 48 | B7: =A7&"/25" -> 48/25 | C7: =4 +4 +4 -> 12 | F7: =LET( intervallo, C7:E7, ore_totali_reali, SUMPRODUCT( INT(intervallo) + (intervallo - INT(intervallo)) * 100 / 60 ), risultato_ore_intere, INT(ore_totali_reali), risultato_minuti_fittizi, (ore_totali_reali - risultato_ore_intere) * 60 / 100, risultato_ore_intere + risultato_minuti_fittizi ) -> 12 | G7: =LET( intervallo, D7:E7, ore_totali_reali, SUMPRODUCT( INT(intervallo) + (intervallo - INT(intervallo)) * 100 / 60 ), risultato_ore_intere, INT(ore_totali_reali), risultato_minuti_fittizi, (ore_totali_reali - risultato_ore_intere) * 60 / 100, risultato_ore_intere + risultato_minuti_fittizi ) -> 0
A8: 49 | B8: =A8&"/25" -> 49/25 | C8: =4 +4 +8 +8 -> 24 | F8: =LET( intervallo, C8:E8, ore_totali_reali, SUMPRODUCT( INT(intervallo) + (intervallo - INT(intervallo)) * 100 / 60 ), risultato_ore_intere, INT(ore_totali_reali), risultato_minuti_fittizi, (ore_totali_reali - risultato_ore_intere) * 60 / 100, risultato_ore_intere + risultato_minuti_fittizi ) -> 24 | G8: =LET( intervallo, D8:E8, ore_totali_reali, SUMPRODUCT( INT(intervallo) + (intervallo - INT(intervallo)) * 100 / 60 ), risultato_ore_intere, INT(ore_totali_reali), risultato_minuti_fittizi, (ore_totali_reali - risultato_ore_intere) * 60 / 100, risultato_ore_intere + risultato_minuti_fittizi ) -> 0
A9: 50 | B9: =A9&"/25" -> 50/25 | C9: =4 + 8 -> 12 | F9: =LET( intervallo, C9:E9, ore_totali_reali, SUMPRODUCT( INT(intervallo) + (intervallo - INT(intervallo)) * 100 / 60 ), risultato_ore_intere, INT(ore_totali_reali), risultato_minuti_fittizi, (ore_totali_reali - risultato_ore_intere) * 60 / 100, risultato_ore_intere + risultato_minuti_fittizi ) -> 12 | G9: =LET( intervallo, D9:E9, ore_totali_reali, SUMPRODUCT( INT(intervallo) + (intervallo - INT(intervallo)) * 100 / 60 ), risultato_ore_intere, INT(ore_totali_reali), risultato_minuti_fittizi, (ore_totali_reali - risultato_ore_intere) * 60 / 100, risultato_ore_intere + risultato_minuti_fittizi ) -> 0
A10: 51 | B10: =A10&"/25" -> 51/25 | C10: =4 +4 +4 +4 -> 16 | F10: =LET( intervallo, C10:E10, ore_totali_reali, SUMPRODUCT( INT(intervallo) + (intervallo - INT(intervallo)) * 100 / 60 ), risultato_ore_intere, INT(ore_totali_reali), risultato_minuti_fittizi, (ore_totali_reali - risultato_ore_intere) * 60 / 100, risultato_ore_intere + risultato_minuti_fittizi ) -> 16 | G10: =LET( intervallo, D10:E10, ore_totali_reali, SUMPRODUCT( INT(intervallo) + (intervallo - INT(intervallo)) * 100 / 60 ), risultato_ore_intere, INT(ore_totali_reali), risultato_minuti_fittizi, (ore_totali_reali - risultato_ore_intere) * 60 / 100, risultato_ore_intere + risultato_minuti_fittizi ) -> 0
A11: 52 | B11: =A11&"/25" -> 52/25 | F11: =LET( intervallo, C11:E11, ore_totali_reali, SUMPRODUCT( INT(intervallo) + (intervallo - INT(intervallo)) * 100 / 60 ), risultato_ore_intere, INT(ore_totali_reali), risultato_minuti_fittizi, (ore_totali_reali - risultato_ore_intere) * 60 / 100, risultato_ore_intere + risultato_minuti_fittizi ) -> 0 | G11: =LET( intervallo, D11:E11, ore_totali_reali, SUMPRODUCT( INT(intervallo) + (intervallo - INT(intervallo)) * 100 / 60 ), risultato_ore_intere, INT(ore_totali_reali), risultato_minuti_fittizi, (ore_totali_reali - risultato_ore_intere) * 60 / 100, risultato_ore_intere + risultato_minuti_fittizi ) -> 0
A12: 1 | B12: =A12&"/26" -> 1/26 | F12: =LET( intervallo, C12:E12, ore_totali_reali, SUMPRODUCT( INT(intervallo) + (intervallo - INT(intervallo)) * 100 / 60 ), risultato_ore_intere, INT(ore_totali_reali), risultato_minuti_fittizi, (ore_totali_reali - risultato_ore_intere) * 60 / 100, risultato_ore_intere + risultato_minuti_fittizi ) -> 0 | G12: =LET( intervallo, D12:E12, ore_totali_reali, SUMPRODUCT( INT(intervallo) + (intervallo - INT(intervallo)) * 100 / 60 ), risultato_ore_intere, INT(ore_totali_reali), risultato_minuti_fittizi, (ore_totali_reali - risultato_ore_intere) * 60 / 100, risultato_ore_intere + risultato_minuti_fittizi ) -> 0
A13: 2 | B13: =A13&"/26" -> 2/26 | C13: =0 +0 -> 0 | F13: =LET( intervallo, C13:E13, ore_totali_reali, SUMPRODUCT( INT(intervallo) + (intervallo - INT(intervallo)) * 100 / 60 ), risultato_ore_intere, INT(ore_totali_reali), risultato_minuti_fittizi, (ore_totali_reali - risultato_ore_intere) * 60 / 100, risultato_ore_intere + risultato_minuti_fittizi ) -> 0 | G13: =LET( intervallo, D13:E13, ore_totali_reali, SUMPRODUCT( INT(intervallo) + (intervallo - INT(intervallo)) * 100 / 60 ), risultato_ore_intere, INT(ore_totali_reali), risultato_minuti_fittizi, (ore_totali_reali - risultato_ore_intere) * 60 / 100, risultato_ore_intere + risultato_minuti_fittizi ) -> 0
A14: 3 | B14: =A14&"/26" -> 3/26 | F14: =LET( intervallo, C14:E14, ore_totali_reali, SUMPRODUCT( INT(intervallo) + (intervallo - INT(intervallo)) * 100 / 60 ), risultato_ore_intere, INT(ore_totali_reali), risultato_minuti_fittizi, (ore_totali_reali - risultato_ore_intere) * 60 / 100, risultato_ore_intere + risultato_minuti_fittizi ) -> 0 | G14: =LET( intervallo, D14:E14, ore_totali_reali, SUMPRODUCT( INT(intervallo) + (intervallo - INT(intervallo)) * 100 / 60 ), risultato_ore_intere, INT(ore_totali_reali), risultato_minuti_fittizi, (ore_totali_reali - risultato_ore_intere) * 60 / 100, risultato_ore_intere + risultato_minuti_fittizi ) -> 0
A15: 4 | B15: =A15&"/26" -> 4/26 | F15: =LET( intervallo, C15:E15, ore_totali_reali, SUMPRODUCT( INT(intervallo) + (intervallo - INT(intervallo)) * 100 / 60 ), risultato_ore_intere, INT(ore_totali_reali), risultato_minuti_fittizi, (ore_totali_reali - risultato_ore_intere) * 60 / 100, risultato_ore_intere + risultato_minuti_fittizi ) -> 0 | G15: =LET( intervallo, D15:E15, ore_totali_reali, SUMPRODUCT( INT(intervallo) + (intervallo - INT(intervallo)) * 100 / 60 ), risultato_ore_intere, INT(ore_totali_reali), risultato_minuti_fittizi, (ore_totali_reali - risultato_ore_intere) * 60 / 100, risultato_ore_intere + risultato_minuti_fittizi ) -> 0
A16: 5 | B16: =A16&"/26" -> 5/26 | F16: =LET( intervallo, C16:E16, ore_totali_reali, SUMPRODUCT( INT(intervallo) + (intervallo - INT(intervallo)) * 100 / 60 ), risultato_ore_intere, INT(ore_totali_reali), risultato_minuti_fittizi, (ore_totali_reali - risultato_ore_intere) * 60 / 100, risultato_ore_intere + risultato_minuti_fittizi ) -> 0 | G16: =LET( intervallo, D16:E16, ore_totali_reali, SUMPRODUCT( INT(intervallo) + (intervallo - INT(intervallo)) * 100 / 60 ), risultato_ore_intere, INT(ore_totali_reali), risultato_minuti_fittizi, (ore_totali_reali - risultato_ore_intere) * 60 / 100, risultato_ore_intere + risultato_minuti_fittizi ) -> 0
A17: 6 | B17: =A17&"/26" -> 6/26 | F17: =LET( intervallo, C17:E17, ore_totali_reali, SUMPRODUCT( INT(intervallo) + (intervallo - INT(intervallo)) * 100 / 60 ), risultato_ore_intere, INT(ore_totali_reali), risultato_minuti_fittizi, (ore_totali_reali - risultato_ore_intere) * 60 / 100, risultato_ore_intere + risultato_minuti_fittizi ) -> 0 | G17: =LET( intervallo, D17:E17, ore_totali_reali, SUMPRODUCT( INT(intervallo) + (intervallo - INT(intervallo)) * 100 / 60 ), risultato_ore_intere, INT(ore_totali_reali), risultato_minuti_fittizi, (ore_totali_reali - risultato_ore_intere) * 60 / 100, risultato_ore_intere + risultato_minuti_fittizi ) -> 0
A18: 7 | B18: =A18&"/26" -> 7/26 | F18: =LET( intervallo, C18:E18, ore_totali_reali, SUMPRODUCT( INT(intervallo) + (intervallo - INT(intervallo)) * 100 / 60 ), risultato_ore_intere, INT(ore_totali_reali), risultato_minuti_fittizi, (ore_totali_reali - risultato_ore_intere) * 60 / 100, risultato_ore_intere + risultato_minuti_fittizi ) -> 0 | G18: =LET( intervallo, D18:E18, ore_totali_reali, SUMPRODUCT( INT(intervallo) + (intervallo - INT(intervallo)) * 100 / 60 ), risultato_ore_intere, INT(ore_totali_reali), risultato_minuti_fittizi, (ore_totali_reali - risultato_ore_intere) * 60 / 100, risultato_ore_intere + risultato_minuti_fittizi ) -> 0
A19: 8 | B19: =A19&"/26" -> 8/26 | F19: =LET( intervallo, C19:E19, ore_totali_reali, SUMPRODUCT( INT(intervallo) + (intervallo - INT(intervallo)) * 100 / 60 ), risultato_ore_intere, INT(ore_totali_reali), risultato_minuti_fittizi, (ore_totali_reali - risultato_ore_intere) * 60 / 100, risultato_ore_intere + risultato_minuti_fittizi ) -> 0 | G19: =LET( intervallo, D19:E19, ore_totali_reali, SUMPRODUCT( INT(intervallo) + (intervallo - INT(intervallo)) * 100 / 60 ), risultato_ore_intere, INT(ore_totali_reali), risultato_minuti_fittizi, (ore_totali_reali - risultato_ore_intere) * 60 / 100, risultato_ore_intere + risultato_minuti_fittizi ) -> 0
A20: 9 | B20: =A20&"/26" -> 9/26 | F20: =LET( intervallo, C20:E20, ore_totali_reali, SUMPRODUCT( INT(intervallo) + (intervallo - INT(intervallo)) * 100 / 60 ), risultato_ore_intere, INT(ore_totali_reali), risultato_minuti_fittizi, (ore_totali_reali - risultato_ore_intere) * 60 / 100, risultato_ore_intere + risultato_minuti_fittizi ) -> 0 | G20: =LET( intervallo, D20:E20, ore_totali_reali, SUMPRODUCT( INT(intervallo) + (intervallo - INT(intervallo)) * 100 / 60 ), risultato_ore_intere, INT(ore_totali_reali), risultato_minuti_fittizi, (ore_totali_reali - risultato_ore_intere) * 60 / 100, risultato_ore_intere + risultato_minuti_fittizi ) -> 0
A21: 10 | B21: =A21&"/26" -> 10/26 | F21: =LET( intervallo, C21:E21, ore_totali_reali, SUMPRODUCT( INT(intervallo) + (intervallo - INT(intervallo)) * 100 / 60 ), risultato_ore_intere, INT(ore_totali_reali), risultato_minuti_fittizi, (ore_totali_reali - risultato_ore_intere) * 60 / 100, risultato_ore_intere + risultato_minuti_fittizi ) -> 0 | G21: =LET( intervallo, D21:E21, ore_totali_reali, SUMPRODUCT( INT(intervallo) + (intervallo - INT(intervallo)) * 100 / 60 ), risultato_ore_intere, INT(ore_totali_reali), risultato_minuti_fittizi, (ore_totali_reali - risultato_ore_intere) * 60 / 100, risultato_ore_intere + risultato_minuti_fittizi ) -> 0
A22: 11 | B22: =A22&"/26" -> 11/26 | F22: =LET( intervallo, C22:E22, ore_totali_reali, SUMPRODUCT( INT(intervallo) + (intervallo - INT(intervallo)) * 100 / 60 ), risultato_ore_intere, INT(ore_totali_reali), risultato_minuti_fittizi, (ore_totali_reali - risultato_ore_intere) * 60 / 100, risultato_ore_intere + risultato_minuti_fittizi ) -> 0 | G22: =LET( intervallo, D22:E22, ore_totali_reali, SUMPRODUCT( INT(intervallo) + (intervallo - INT(intervallo)) * 100 / 60 ), risultato_ore_intere, INT(ore_totali_reali), risultato_minuti_fittizi, (ore_totali_reali - risultato_ore_intere) * 60 / 100, risultato_ore_intere + risultato_minuti_fittizi ) -> 0
A23: 12 | B23: =A23&"/26" -> 12/26 | F23: =LET( intervallo, C23:E23, ore_totali_reali, SUMPRODUCT( INT(intervallo) + (intervallo - INT(intervallo)) * 100 / 60 ), risultato_ore_intere, INT(ore_totali_reali), risultato_minuti_fittizi, (ore_totali_reali - risultato_ore_intere) * 60 / 100, risultato_ore_intere + risultato_minuti_fittizi ) -> 0 | G23: =LET( intervallo, D23:E23, ore_totali_reali, SUMPRODUCT( INT(intervallo) + (intervallo - INT(intervallo)) * 100 / 60 ), risultato_ore_intere, INT(ore_totali_reali), risultato_minuti_fittizi, (ore_totali_reali - risultato_ore_intere) * 60 / 100, risultato_ore_intere + risultato_minuti_fittizi ) -> 0
A24: 13 | B24: =A24&"/26" -> 13/26 | F24: =LET( intervallo, C24:E24, ore_totali_reali, SUMPRODUCT( INT(intervallo) + (intervallo - INT(intervallo)) * 100 / 60 ), risultato_ore_intere, INT(ore_totali_reali), risultato_minuti_fittizi, (ore_totali_reali - risultato_ore_intere) * 60 / 100, risultato_ore_intere + risultato_minuti_fittizi ) -> 0 | G24: =LET( intervallo, D24:E24, ore_totali_reali, SUMPRODUCT( INT(intervallo) + (intervallo - INT(intervallo)) * 100 / 60 ), risultato_ore_intere, INT(ore_totali_reali), risultato_minuti_fittizi, (ore_totali_reali - risultato_ore_intere) * 60 / 100, risultato_ore_intere + risultato_minuti_fittizi ) -> 0
A25: 14 | B25: =A25&"/26" -> 14/26 | F25: =LET( intervallo, C25:E25, ore_totali_reali, SUMPRODUCT( INT(intervallo) + (intervallo - INT(intervallo)) * 100 / 60 ), risultato_ore_intere, INT(ore_totali_reali), risultato_minuti_fittizi, (ore_totali_reali - risultato_ore_intere) * 60 / 100, risultato_ore_intere + risultato_minuti_fittizi ) -> 0 | G25: =LET( intervallo, D25:E25, ore_totali_reali, SUMPRODUCT( INT(intervallo) + (intervallo - INT(intervallo)) * 100 / 60 ), risultato_ore_intere, INT(ore_totali_reali), risultato_minuti_fittizi, (ore_totali_reali - risultato_ore_intere) * 60 / 100, risultato_ore_intere + risultato_minuti_fittizi ) -> 0
... A66: 55 | B66: =A66&"/26" -> 55/26 | F66: =LET( intervallo, C66:E66, ore_totali_reali, SUMPRODUCT( INT(intervallo) + (intervallo - INT(intervallo)) * 100 / 60 ), risultato_ore_intere, INT(ore_totali_reali), risultato_minuti_fittizi, (ore_totali_reali - risultato_ore_intere) * 60 / 100, risultato_ore_intere + risultato_minuti_fittizi ) -> 0 | G66: =LET( intervallo, D66:E66, ore_totali_reali, SUMPRODUCT( INT(intervallo) + (intervallo - INT(intervallo)) * 100 / 60 ), risultato_ore_intere, INT(ore_totali_reali), risultato_minuti_fittizi, (ore_totali_reali - risultato_ore_intere) * 60 / 100, risultato_ore_intere + risultato_minuti_fittizi ) -> 0
A67: 1 | B67: =A67&"/27" -> 1/27 | F67: =LET( intervallo, C67:E67, ore_totali_reali, SUMPRODUCT( INT(intervallo) + (intervallo - INT(intervallo)) * 100 / 60 ), risultato_ore_intere, INT(ore_totali_reali), risultato_minuti_fittizi, (ore_totali_reali - risultato_ore_intere) * 60 / 100, risultato_ore_intere + risultato_minuti_fittizi ) -> 0 | G67: =LET( intervallo, D67:E67, ore_totali_reali, SUMPRODUCT( INT(intervallo) + (intervallo - INT(intervallo)) * 100 / 60 ), risultato_ore_intere, INT(ore_totali_reali), risultato_minuti_fittizi, (ore_totali_reali - risultato_ore_intere) * 60 / 100, risultato_ore_intere + risultato_minuti_fittizi ) -> 0
A68: 2 | B68: =A68&"/27" -> 2/27 | F68: =LET( intervallo, C68:E68, ore_totali_reali, SUMPRODUCT( INT(intervallo) + (intervallo - INT(intervallo)) * 100 / 60 ), risultato_ore_intere, INT(ore_totali_reali), risultato_minuti_fittizi, (ore_totali_reali - risultato_ore_intere) * 60 / 100, risultato_ore_intere + risultato_minuti_fittizi ) -> 0 | G68: =LET( intervallo, D68:E68, ore_totali_reali, SUMPRODUCT( INT(intervallo) + (intervallo - INT(intervallo)) * 100 / 60 ), risultato_ore_intere, INT(ore_totali_reali), risultato_minuti_fittizi, (ore_totali_reali - risultato_ore_intere) * 60 / 100, risultato_ore_intere + risultato_minuti_fittizi ) -> 0
A69: 3 | B69: =A69&"/27" -> 3/27 | F69: =LET( intervallo, C69:E69, ore_totali_reali, SUMPRODUCT( INT(intervallo) + (intervallo - INT(intervallo)) * 100 / 60 ), risultato_ore_intere, INT(ore_totali_reali), risultato_minuti_fittizi, (ore_totali_reali - risultato_ore_intere) * 60 / 100, risultato_ore_intere + risultato_minuti_fittizi ) -> 0 | G69: =LET( intervallo, D69:E69, ore_totali_reali, SUMPRODUCT( INT(intervallo) + (intervallo - INT(intervallo)) * 100 / 60 ), risultato_ore_intere, INT(ore_totali_reali), risultato_minuti_fittizi, (ore_totali_reali - risultato_ore_intere) * 60 / 100, risultato_ore_intere + risultato_minuti_fittizi ) -> 0
A70: 4 | B70: =A70&"/27" -> 4/27 | F70: =LET( intervallo, C70:E70, ore_totali_reali, SUMPRODUCT( INT(intervallo) + (intervallo - INT(intervallo)) * 100 / 60 ), risultato_ore_intere, INT(ore_totali_reali), risultato_minuti_fittizi, (ore_totali_reali - risultato_ore_intere) * 60 / 100, risultato_ore_intere + risultato_minuti_fittizi ) -> 0 | G70: =LET( intervallo, D70:E70, ore_totali_reali, SUMPRODUCT( INT(intervallo) + (intervallo - INT(intervallo)) * 100 / 60 ), risultato_ore_intere, INT(ore_totali_reali), risultato_minuti_fittizi, (ore_totali_reali - risultato_ore_intere) * 60 / 100, risultato_ore_intere + risultato_minuti_fittizi ) -> 0
A71: 5 | B71: =A71&"/27" -> 5/27 | F71: =LET( intervallo, C71:E71, ore_totali_reali, SUMPRODUCT( INT(intervallo) + (intervallo - INT(intervallo)) * 100 / 60 ), risultato_ore_intere, INT(ore_totali_reali), risultato_minuti_fittizi, (ore_totali_reali - risultato_ore_intere) * 60 / 100, risultato_ore_intere + risultato_minuti_fittizi ) -> 0 | G71: =LET( intervallo, D71:E71, ore_totali_reali, SUMPRODUCT( INT(intervallo) + (intervallo - INT(intervallo)) * 100 / 60 ), risultato_ore_intere, INT(ore_totali_reali), risultato_minuti_fittizi, (ore_totali_reali - risultato_ore_intere) * 60 / 100, risultato_ore_intere + risultato_minuti_fittizi ) -> 0
A72: 6 | B72: =A72&"/27" -> 6/27 | F72: =LET( intervallo, C72:E72, ore_totali_reali, SUMPRODUCT( INT(intervallo) + (intervallo - INT(intervallo)) * 100 / 60 ), risultato_ore_intere, INT(ore_totali_reali), risultato_minuti_fittizi, (ore_totali_reali - risultato_ore_intere) * 60 / 100, risultato_ore_intere + risultato_minuti_fittizi ) -> 0 | G72: =LET( intervallo, D72:E72, ore_totali_reali, SUMPRODUCT( INT(intervallo) + (intervallo - INT(intervallo)) * 100 / 60 ), risultato_ore_intere, INT(ore_totali_reali), risultato_minuti_fittizi, (ore_totali_reali - risultato_ore_intere) * 60 / 100, risultato_ore_intere + risultato_minuti_fittizi ) -> 0
A73: 7 | B73: =A73&"/27" -> 7/27 | F73: =LET( intervallo, C73:E73, ore_totali_reali, SUMPRODUCT( INT(intervallo) + (intervallo - INT(intervallo)) * 100 / 60 ), risultato_ore_intere, INT(ore_totali_reali), risultato_minuti_fittizi, (ore_totali_reali - risultato_ore_intere) * 60 / 100, risultato_ore_intere + risultato_minuti_fittizi ) -> 0 | G73: =LET( intervallo, D73:E73, ore_totali_reali, SUMPRODUCT( INT(intervallo) + (intervallo - INT(intervallo)) * 100 / 60 ), risultato_ore_intere, INT(ore_totali_reali), risultato_minuti_fittizi, (ore_totali_reali - risultato_ore_intere) * 60 / 100, risultato_ore_intere + risultato_minuti_fittizi ) -> 0
A74: 8 | B74: =A74&"/27" -> 8/27 | F74: =LET( intervallo, C74:E74, ore_totali_reali, SUMPRODUCT( INT(intervallo) + (intervallo - INT(intervallo)) * 100 / 60 ), risultato_ore_intere, INT(ore_totali_reali), risultato_minuti_fittizi, (ore_totali_reali - risultato_ore_intere) * 60 / 100, risultato_ore_intere + risultato_minuti_fittizi ) -> 0 | G74: =LET( intervallo, D74:E74, ore_totali_reali, SUMPRODUCT( INT(intervallo) + (intervallo - INT(intervallo)) * 100 / 60 ), risultato_ore_intere, INT(ore_totali_reali), risultato_minuti_fittizi, (ore_totali_reali - risultato_ore_intere) * 60 / 100, risultato_ore_intere + risultato_minuti_fittizi ) -> 0
A75: 9 | B75: =A75&"/27" -> 9/27 | F75: =LET( intervallo, C75:E75, ore_totali_reali, SUMPRODUCT( INT(intervallo) + (intervallo - INT(intervallo)) * 100 / 60 ), risultato_ore_intere, INT(ore_totali_reali), risultato_minuti_fittizi, (ore_totali_reali - risultato_ore_intere) * 60 / 100, risultato_ore_intere + risultato_minuti_fittizi ) -> 0 | G75: =LET( intervallo, D75:E75, ore_totali_reali, SUMPRODUCT( INT(intervallo) + (intervallo - INT(intervallo)) * 100 / 60 ), risultato_ore_intere, INT(ore_totali_reali), risultato_minuti_fittizi, (ore_totali_reali - risultato_ore_intere) * 60 / 100, risultato_ore_intere + risultato_minuti_fittizi ) -> 0
A76: 10 | B76: =A76&"/27" -> 10/27 | F76: =LET( intervallo, C76:E76, ore_totali_reali, SUMPRODUCT( INT(intervallo) + (intervallo - INT(intervallo)) * 100 / 60 ), risultato_ore_intere, INT(ore_totali_reali), risultato_minuti_fittizi, (ore_totali_reali - risultato_ore_intere) * 60 / 100, risultato_ore_intere + risultato_minuti_fittizi ) -> 0 | G76: =LET( intervallo, D76:E76, ore_totali_reali, SUMPRODUCT( INT(intervallo) + (intervallo - INT(intervallo)) * 100 / 60 ), risultato_ore_intere, INT(ore_totali_reali), risultato_minuti_fittizi, (ore_totali_reali - risultato_ore_intere) * 60 / 100, risultato_ore_intere + risultato_minuti_fittizi ) -> 0
A77: 11 | B77: =A77&"/27" -> 11/27 | F77: =LET( intervallo, C77:E77, ore_totali_reali, SUMPRODUCT( INT(intervallo) + (intervallo - INT(intervallo)) * 100 / 60 ), risultato_ore_intere, INT(ore_totali_reali), risultato_minuti_fittizi, (ore_totali_reali - risultato_ore_intere) * 60 / 100, risultato_ore_intere + risultato_minuti_fittizi ) -> 0 | G77: =LET( intervallo, D77:E77, ore_totali_reali, SUMPRODUCT( INT(intervallo) + (intervallo - INT(intervallo)) * 100 / 60 ), risultato_ore_intere, INT(ore_totali_reali), risultato_minuti_fittizi, (ore_totali_reali - risultato_ore_intere) * 60 / 100, risultato_ore_intere + risultato_minuti_fittizi ) -> 0
A78: 12 | B78: =A78&"/27" -> 12/27 | F78: =LET( intervallo, C78:E78, ore_totali_reali, SUMPRODUCT( INT(intervallo) + (intervallo - INT(intervallo)) * 100 / 60 ), risultato_ore_intere, INT(ore_totali_reali), risultato_minuti_fittizi, (ore_totali_reali - risultato_ore_intere) * 60 / 100, risultato_ore_intere + risultato_minuti_fittizi ) -> 0 | G78: =LET( intervallo, D78:E78, ore_totali_reali, SUMPRODUCT( INT(intervallo) + (intervallo - INT(intervallo)) * 100 / 60 ), risultato_ore_intere, INT(ore_totali_reali), risultato_minuti_fittizi, (ore_totali_reali - risultato_ore_intere) * 60 / 100, risultato_ore_intere + risultato_minuti_fittizi ) -> 0
... A99: 33 | B99: =A99&"/27" -> 33/27 | F99: =LET( intervallo, C99:E99, ore_totali_reali, SUMPRODUCT( INT(intervallo) + (intervallo - INT(intervallo)) * 100 / 60 ), risultato_ore_intere, INT(ore_totali_reali), risultato_minuti_fittizi, (ore_totali_reali - risultato_ore_intere) * 60 / 100, risultato_ore_intere + risultato_minuti_fittizi ) -> 0 | G99: =LET( intervallo, D99:E99, ore_totali_reali, SUMPRODUCT( INT(intervallo) + (intervallo - INT(intervallo)) * 100 / 60 ), risultato_ore_intere, INT(ore_totali_reali), risultato_minuti_fittizi, (ore_totali_reali - risultato_ore_intere) * 60 / 100, risultato_ore_intere + risultato_minuti_fittizi ) -> 0

Sheet V_LISTA
D1: DATE out | E1: 46023 | F1: FATTE | G1: 8 | K1: ORDINE | L1: SKU | O1: SETT. | P1: 46020 | S1: per ora la visualizzazione è in base alle attività "che escono"
K2: Ener | L2: n° Att
A3: CHECK | B3: DATA RIM. | C3: SKU | D3: STATO | E3: DESCRIZIONE | F3: PR | G3: L. T. | H3: EXEC | I3: WATT | K3: =P1 -> 46020 | M3: =K3+1 -> 46021 | O3: =M3+1 -> 46022 | Q3: =O3+1 -> 46023 | S3: =Q3+1 -> 46024 | U3: =S3+1 -> 46025 | W3: =U3+1 -> 46026
C4: =IFERROR(__xludf.DUMMYFUNCTION("QUERY({LISTA_IN!A2:J150 , ARRAYFORMULA(SWITCH(LISTA_IN!C2:C150, ""A+++"", 1, ""A"", 2, ""B"", 3, ""C"", 4, ""C---"", 5, 6)) , ARRAYFORMULA(SWITCH(LISTA_IN!D2:D150, ""A+++"", 1, ""A"", 2, ""B"", 3, ""C"", 4, ""C---"", 5, 6)) , ARRAYFORMULA(SWITCH("&"LISTA_IN!E2:E150, ""A+++"", 1, ""A"", 2, ""B"", 3, ""C"", 4, ""C---"", 5, 6)) , ARRAYFORMULA(SWITCH(LISTA_IN!F2:F150, ""A+++"", 1, ""A"", 2, ""B"", 3, ""C"", 4, ""C---"", 5, 6)) }, ""SELECT Col1, Col10, Col2, Col3, Col4, Col5, Col6 WHERE Col1 <> '"&"SKU' AND Col2 IS NOT NULL "" & IFS( D1=""DATE in"", "" AND Col7 = date '"" & TEXT(E1, ""yyyy-mm-dd"") & ""'"", D1=""DATE out"", "" AND Col8 = date '"" & TEXT(E1, ""yyyy-mm-dd"") & ""'"", D1=""CRITICO"", "" ORDER BY Col11 ASC, Col8 ASC"", "&" D1=""WATT"", "" ORDER BY Col14 ASC"", D1=""EXEC"", "" ORDER BY Col13 ASC"", TRUE, """" ), 0)"),"SKU-2") -> SKU-2 | D4: =IFERROR(__xludf.DUMMYFUNCTION("""COMPUTED_VALUE"""),"da fare") -> da fare | E4: =IFERROR(__xludf.DUMMYFUNCTION("""COMPUTED_VALUE"""),"Setup Ambiente: Configurazione repository Git e automazione Push") -> Setup Ambiente: Configurazione repository Git e automazione Push | F4: =IFERROR(__xludf.DUMMYFUNCTION("""COMPUTED_VALUE"""),"A+++") -> A+++ | G4: =IFERROR(__xludf.DUMMYFUNCTION("""COMPUTED_VALUE"""),"A") -> A | H4: =IFERROR(__xludf.DUMMYFUNCTION("""COMPUTED_VALUE"""),"C") -> C | I4: =IFERROR(__xludf.DUMMYFUNCTION("""COMPUTED_VALUE"""),"B") -> B | K4: =IFERROR(__xludf.DUMMYFUNCTION("IFERROR(VLOOKUP( ROUND(AVERAGE(ARRAYFORMULA(IFERROR(VLOOKUP(FILTER(LISTA_IN!$F$2:$F150, LISTA_IN!$H$2:$H150 = K3), GESTIONE!$P$2:$Q$6, 2, 0)))), 0), {GESTIONE!$Q$2:$Q$6, GESTIONE!$P$2:$P$6}, 2, 0), ""-"")"),"-") -> - | L4: =COUNTIF(LISTA_IN!$H$2:$H150, K3) -> 0 | M4: =IFERROR(__xludf.DUMMYFUNCTION("IFERROR(VLOOKUP( ROUND(AVERAGE(ARRAYFORMULA(IFERROR(VLOOKUP(FILTER(LISTA_IN!$F$2:$F150, LISTA_IN!$H$2:$H150 = M3), GESTIONE!$P$2:$Q$6, 2, 0)))), 0), {GESTIONE!$Q$2:$Q$6, GESTIONE!$P$2:$P$6}, 2, 0), ""-"")"),"A") -> A | N4: =COUNTIF(LISTA_IN!$H$2:$H150, M3) -> 1 | O4: =IFERROR(__xludf.DUMMYFUNCTION("IFERROR(VLOOKUP( ROUND(AVERAGE(ARRAYFORMULA(IFERROR(VLOOKUP(FILTER(LISTA_IN!$F$2:$F150, LISTA_IN!$H$2:$H150 = O3), GESTIONE!$P$2:$Q$6, 2, 0)))), 0), {GESTIONE!$Q$2:$Q$6, GESTIONE!$P$2:$P$6}, 2, 0), ""-"")"),"B") -> B | P4: =COUNTIF(LISTA_IN!$H$2:$H150, O3) -> 6 | Q4: =IFERROR(__xludf.DUMMYFUNCTION("IFERROR(VLOOKUP( ROUND(AVERAGE(ARRAYFORMULA(IFERROR(VLOOKUP(FILTER(LISTA_IN!$F$2:$F150, LISTA_IN!$H$2:$H150 = Q3), GESTIONE!$P$2:$Q$6, 2, 0)))), 0), {GESTIONE!$Q$2:$Q$6, GESTIONE!$P$2:$P$6}, 2, 0), ""-"")"),"B") -> B | R4: =COUNTIF(LISTA_IN!$H$2:$H150, Q3) -> 4 | S4: =IFERROR(__xludf.DUMMYFUNCTION("IFERROR(VLOOKUP( ROUND(AVERAGE(ARRAYFORMULA(IFERROR(VLOOKUP(FILTER(LISTA_IN!$F$2:$F150, LISTA_IN!$H$2:$H150 = S3), GESTIONE!$P$2:$Q$6, 2, 0)))), 0), {GESTIONE!$Q$2:$Q$6, GESTIONE!$P$2:$P$6}, 2, 0), ""-"")"),"B") -> B | T4: =COUNTIF(LISTA_IN!$H$2:$H150, S3) -> 4 | U4: =IFERROR(__xludf.DUMMYFUNCTION("IFERROR(VLOOKUP( ROUND(AVERAGE(ARRAYFORMULA(IFERROR(VLOOKUP(FILTER(LISTA_IN!$F$2:$F150, LISTA_IN!$H$2:$H150 = U3), GESTIONE!$P$2:$Q$6, 2, 0)))), 0), {GESTIONE!$Q$2:$Q$6, GESTIONE!$P$2:$P$6}, 2, 0), ""-"")"),"A") -> A | V4: =COUNTIF(LISTA_IN!$H$2:$H150, U3) -> 2 | W4: =IFERROR(__xludf.DUMMYFUNCTION("IFERROR(VLOOKUP( ROUND(AVERAGE(ARRAYFORMULA(IFERROR(VLOOKUP(FILTER(LISTA_IN!$F$2:$F150, LISTA_IN!$H$2:$H150 = W3), GESTIONE!$P$2:$Q$6, 2, 0)))), 0), {GESTIONE!$Q$2:$Q$6, GESTIONE!$P$2:$P$6}, 2, 0), ""-"")"),"B") -> B | X4: =COUNTIF(LISTA_IN!$H$2:$H150, W3) -> 3
C5: =IFERROR(__xludf.DUMMYFUNCTION("""COMPUTED_VALUE"""),"SKU-3") -> SKU-3 | D5: =IFERROR(__xludf.DUMMYFUNCTION("""COMPUTED_VALUE"""),"da fare") -> da fare | E5: =IFERROR(__xludf.DUMMYFUNCTION("""COMPUTED_VALUE"""),"Refactoring: Modulo IMPORT_NOTE.gs per gestione errori API") -> Refactoring: Modulo IMPORT_NOTE.gs per gestione errori API | F5: =IFERROR(__xludf.DUMMYFUNCTION("""COMPUTED_VALUE"""),"A+++") -> A+++ | G5: =IFERROR(__xludf.DUMMYFUNCTION("""COMPUTED_VALUE"""),"A") -> A | H5: =IFERROR(__xludf.DUMMYFUNCTION("""COMPUTED_VALUE"""),"C---") -> C--- | I5: =IFERROR(__xludf.DUMMYFUNCTION("""COMPUTED_VALUE"""),"A+++") -> A+++ | K5: =IFERROR(__xludf.DUMMYFUNCTION("IFERROR(TEXTJOIN(CHAR(10), TRUE, ARRAYFORMULA(""- "" & LEFT(QUERY({LISTA_IN!$A$2:$K150 , SWITCH(LISTA_IN!$F$2:$F150, ""A+++"", 1, ""A"", 2, ""B"", 3, ""C"", 4, ""C---"", 5, 6) , SWITCH(LISTA_IN!$E$2:$E150, ""A+++"", 1, ""A"", 2, ""B"", 3, ""C"&""", 4, ""C---"", 5, 6) , SWITCH(LISTA_IN!$C$2:$C150, ""A+++"", 1, ""A"", 2, ""B"", 3, ""C"", 4, ""C---"", 5, 6)}, ""SELECT Col2 WHERE Col8 = date '"" & TEXT(K3, ""yyyy-mm-dd"") & ""' ORDER BY "" & SWITCH($L$1, ""energia"&""", ""Col12"", ""tempo"", ""Col13"", ""priorità"", ""Col14"", ""SKU"", ""Col1"", ""Col1"") & "" ASC LABEL Col2 ''""), 15)) ), ""nessuna attività"")"),"nessuna attività") -> nessuna attività | M5: =IFERROR(__xludf.DUMMYFUNCTION("IFERROR(TEXTJOIN(CHAR(10), TRUE, ARRAYFORMULA(""- "" & LEFT(QUERY({LISTA_IN!$A$2:$K150 , SWITCH(LISTA_IN!$F$2:$F150, ""A+++"", 1, ""A"", 2, ""B"", 3, ""C"", 4, ""C---"", 5, 6) , SWITCH(LISTA_IN!$E$2:$E150, ""A+++"", 1, ""A"", 2, ""B"", 3, ""C"&""", 4, ""C---"", 5, 6) , SWITCH(LISTA_IN!$C$2:$C150, ""A+++"", 1, ""A"", 2, ""B"", 3, ""C"", 4, ""C---"", 5, 6)}, ""SELECT Col2 WHERE Col8 = date '"" & TEXT(M3, ""yyyy-mm-dd"") & ""' ORDER BY "" & SWITCH($L$1, ""energia"&""", ""Col12"", ""tempo"", ""Col13"", ""priorità"", ""Col14"", ""SKU"", ""Col1"", ""Col1"") & "" ASC LABEL Col2 ''""), 15)) ), ""nessuna attività"")"),"- data base esc =") -> - data base esc = | O5: =IFERROR(__xludf.DUMMYFUNCTION("IFERROR(TEXTJOIN(CHAR(10), TRUE, ARRAYFORMULA(""- "" & LEFT(QUERY({LISTA_IN!$A$2:$K150 , SWITCH(LISTA_IN!$F$2:$F150, ""A+++"", 1, ""A"", 2, ""B"", 3, ""C"", 4, ""C---"", 5, 6) , SWITCH(LISTA_IN!$E$2:$E150, ""A+++"", 1, ""A"", 2, ""B"", 3, ""C"&""", 4, ""C---"", 5, 6) , SWITCH(LISTA_IN!$C$2:$C150, ""A+++"", 1, ""A"", 2, ""B"", 3, ""C"", 4, ""C---"", 5, 6)}, ""SELECT Col2 WHERE Col8 = date '"" & TEXT(O3, ""yyyy-mm-dd"") & ""' ORDER BY "" & SWITCH($L$1, ""energia"&""", ""Col12"", ""tempo"", ""Col13"", ""priorità"", ""Col14"", ""SKU"", ""Col1"", ""Col1"") & "" ASC LABEL Col2 ''""), 15)) ), ""nessuna attività"")"),"- GIT HUB: pulir - GIT HUB: crear - GIT HUB: caric - 20.30 cena con - Aggiornamento p - post linkedin") -> - GIT HUB: pulir - GIT HUB: crear - GIT HUB: caric - 20.30 cena con - Aggiornamento p - post linkedin | Q5: =IFERROR(__xludf.DUMMYFUNCTION("IFERROR(TEXTJOIN(CHAR(10), TRUE, ARRAYFORMULA(""- "" & LEFT(QUERY({LISTA_IN!$A$2:$K150 , SWITCH(LISTA_IN!$F$2:$F150, ""A+++"", 1, ""A"", 2, ""B"", 3, ""C"", 4, ""C---"", 5, 6) , SWITCH(LISTA_IN!$E$2:$E150, ""A+++"", 1, ""A"", 2, ""B"", 3, ""C"&""", 4, ""C---"", 5, 6) , SWITCH(LISTA_IN!$C$2:$C150, ""A+++"", 1, ""A"", 2, ""B"", 3, ""C"", 4, ""C---"", 5, 6)}, ""SELECT Col2 WHERE Col8 = date '"" & TEXT(Q3, ""yyyy-mm-dd"") & ""' ORDER BY "" & SWITCH($L$1, ""energia"&""", ""Col12"", ""tempo"", ""Col13"", ""priorità"", ""Col14"", ""SKU"", ""Col1"", ""Col1"") & "" ASC LABEL Col2 ''""), 15)) ), ""nessuna attività"")"),"- beck up my driv - Setup Ambiente: - mappare meta fi - Refactoring: Mo") -> - beck up my driv - Setup Ambiente: - mappare meta fi - Refactoring: Mo | S5: =IFERROR(__xludf.DUMMYFUNCTION("IFERROR(TEXTJOIN(CHAR(10), TRUE, ARRAYFORMULA(""- "" & LEFT(QUERY({LISTA_IN!$A$2:$K150 , SWITCH(LISTA_IN!$F$2:$F150, ""A+++"", 1, ""A"", 2, ""B"", 3, ""C"", 4, ""C---"", 5, 6) , SWITCH(LISTA_IN!$E$2:$E150, ""A+++"", 1, ""A"", 2, ""B"", 3, ""C"&""", 4, ""C---"", 5, 6) , SWITCH(LISTA_IN!$C$2:$C150, ""A+++"", 1, ""A"", 2, ""B"", 3, ""C"", 4, ""C---"", 5, 6)}, ""SELECT Col2 WHERE Col8 = date '"" & TEXT(S3, ""yyyy-mm-dd"") & ""' ORDER BY "" & SWITCH($L$1, ""energia"&""", ""Col12"", ""tempo"", ""Col13"", ""priorità"", ""Col14"", ""SKU"", ""Col1"", ""Col1"") & "" ASC LABEL Col2 ''""), 15)) ), ""nessuna attività"")"),"- 10.00 inglese - Manutenzione ha - Script Python: - Documentazione:") -> - 10.00 inglese - Manutenzione ha - Script Python: - Documentazione: | U5: =IFERROR(__xludf.DUMMYFUNCTION("IFERROR(TEXTJOIN(CHAR(10), TRUE, ARRAYFORMULA(""- "" & LEFT(QUERY({LISTA_IN!$A$2:$K150 , SWITCH(LISTA_IN!$F$2:$F150, ""A+++"", 1, ""A"", 2, ""B"", 3, ""C"", 4, ""C---"", 5, 6) , SWITCH(LISTA_IN!$E$2:$E150, ""A+++"", 1, ""A"", 2, ""B"", 3, ""C"&""", 4, ""C---"", 5, 6) , SWITCH(LISTA_IN!$C$2:$C150, ""A+++"", 1, ""A"", 2, ""B"", 3, ""C"", 4, ""C---"", 5, 6)}, ""SELECT Col2 WHERE Col8 = date '"" & TEXT(U3, ""yyyy-mm-dd"") & ""' ORDER BY "" & SWITCH($L$1, ""energia"&""", ""Col12"", ""tempo"", ""Col13"", ""priorità"", ""Col14"", ""SKU"", ""Col1"", ""Col1"") & "" ASC LABEL Col2 ''""), 15)) ), ""nessuna attività"")"),"- UI Testing: Val - Formazione: Stu") -> - UI Testing: Val - Formazione: Stu | W5: =IFERROR(__xludf.DUMMYFUNCTION("IFERROR(TEXTJOIN(CHAR(10), TRUE, ARRAYFORMULA(""- "" & LEFT(QUERY({LISTA_IN!$A$2:$K150 , SWITCH(LISTA_IN!$F$2:$F150, ""A+++"", 1, ""A"", 2, ""B"", 3, ""C"", 4, ""C---"", 5, 6) , SWITCH(LISTA_IN!$E$2:$E150, ""A+++"", 1, ""A"", 2, ""B"", 3, ""C"&""", 4, ""C---"", 5, 6) , SWITCH(LISTA_IN!$C$2:$C150, ""A+++"", 1, ""A"", 2, ""B"", 3, ""C"", 4, ""C---"", 5, 6)}, ""SELECT Col2 WHERE Col8 = date '"" & TEXT(W3, ""yyyy-mm-dd"") & ""' ORDER BY "" & SWITCH($L$1, ""energia"&""", ""Col12"", ""tempo"", ""Col13"", ""priorità"", ""Col14"", ""SKU"", ""Col1"", ""Col1"") & "" ASC LABEL Col2 ''""), 15)) ), ""nessuna attività"")"),"- 10.00 inglese - Algoritmi: Eser - Manutenzione: S") -> - 10.00 inglese - Algoritmi: Eser - Manutenzione: S
C6: =IFERROR(__xludf.DUMMYFUNCTION("""COMPUTED_VALUE"""),"SKU-18") -> SKU-18 | D6: =IFERROR(__xludf.DUMMYFUNCTION("""COMPUTED_VALUE"""),"da fare") -> da fare | E6: =IFERROR(__xludf.DUMMYFUNCTION("""COMPUTED_VALUE"""),"beck up my drive") -> beck up my drive | F6: =IFERROR(__xludf.DUMMYFUNCTION("""COMPUTED_VALUE"""),"A+++") -> A+++ | G6: =IFERROR(__xludf.DUMMYFUNCTION("""COMPUTED_VALUE"""),"A") -> A | H6: =IFERROR(__xludf.DUMMYFUNCTION("""COMPUTED_VALUE"""),"A") -> A | I6: =IFERROR(__xludf.DUMMYFUNCTION("""COMPUTED_VALUE"""),"C---") -> C---
C7: =IFERROR(__xludf.DUMMYFUNCTION("""COMPUTED_VALUE"""),"SKU-29") -> SKU-29 | D7: =IFERROR(__xludf.DUMMYFUNCTION("""COMPUTED_VALUE"""),"da fare") -> da fare | E7: =IFERROR(__xludf.DUMMYFUNCTION("""COMPUTED_VALUE"""),"mappare meta file") -> mappare meta file | F7: =IFERROR(__xludf.DUMMYFUNCTION("""COMPUTED_VALUE"""),"A+++") -> A+++ | G7: =IFERROR(__xludf.DUMMYFUNCTION("""COMPUTED_VALUE"""),"A") -> A | H7: =IFERROR(__xludf.DUMMYFUNCTION("""COMPUTED_VALUE"""),"A") -> A | I7: =IFERROR(__xludf.DUMMYFUNCTION("""COMPUTED_VALUE"""),"A") -> A
K12: =W3+1 -> 46027 | M12: =K12+1 -> 46028 | O12: =M12+1 -> 46029 | Q12: =O12+1 -> 46030 | S12: =Q12+1 -> 46031 | U12: =S12+1 -> 46032 | W12: =U12+1 -> 46033
